<?xml version="1.0" encoding="utf-8"?>
<!-- This URDF was automatically created by SolidWorks to URDF Exporter! Originally created by Stephen Brawner (brawner@gmail.com) 
     Commit Version: 1.6.0-4-g7f85cfe  Build Version: 1.6.7995.38578
     For more information, please see http://wiki.ros.org/sw_urdf_exporter -->
<robot
  name="meta_wl">
  <link
    name="base_link">
    <inertial>
      <origin
        xyz="-0.112735140329824 -0.0183723185813253 -0.00945159251618769"
        rpy="0 0 0" />
      <mass
        value="1.65327950844393" />
      <inertia
        ixx="0.00383675118505748"
        ixy="2.79652806831632E-06"
        ixz="-3.99202672316944E-06"
        iyy="0.00362616237244768"
        iyz="0.000352184208953736"
        izz="0.00242396648755098" />
    </inertial>
    <visual>
      <origin
        xyz="0 0 0"
        rpy="0 0 0" />
      <geometry>
        <mesh
          filename="package://meta_wl/meshes/base_link.STL" />
      </geometry>
      <material
        name="">
        <color
          rgba="1 1 1 0.35" />
      </material>
    </visual>
    <collision>
      <origin
        xyz="0 0 0"
        rpy="0 0 0" />
      <geometry>
        <mesh
          filename="package://meta_wl/meshes/base_link.STL" />
      </geometry>
    </collision>
  </link>
  <link
    name="l_upper">
    <inertial>
      <origin
        xyz="0.0671852310993694 1.72114374890327E-18 0.00249999999999975"
        rpy="0 0 0" />
      <mass
        value="0.0344820345885739" />
      <inertia
        ixx="3.92026657716492E-06"
        ixy="2.11758236813575E-21"
        ixz="7.98134345163021E-22"
        iyy="9.12501321073414E-05"
        iyz="1.33270233661788E-21"
        izz="9.50286734754056E-05" />
    </inertial>
    <visual>
      <origin
        xyz="0 0 0"
        rpy="0 0 0" />
      <geometry>
        <mesh
          filename="package://meta_wl/meshes/l_upper.STL" />
      </geometry>
      <material
        name="">
        <color
          rgba="1 1 1 0.35" />
      </material>
    </visual>
    <collision>
      <origin
        xyz="0 0 0"
        rpy="0 0 0" />
      <geometry>
        <mesh
          filename="package://meta_wl/meshes/l_upper.STL" />
      </geometry>
    </collision>
  </link>
  <joint
    name="l_hip"
    type="revolute">
    <origin
      xyz="0.005 0 0"
      rpy="-1.5708 0.89586 1.5708" />
    <parent
      link="base_link" />
    <child
      link="l_upper" />
    <axis
      xyz="0 0 1" />
    <limit
      lower="-0.436"
      upper="0.262"
      effort="0"
      velocity="0" />
  </joint>
  <link
    name="l_lower">
    <inertial>
      <origin
        xyz="0.10506997415943 7.63611994727964E-06 0.00562049568608449"
        rpy="0 0 0" />
      <mass
        value="0.178077513203325" />
      <inertia
        ixx="3.90373009087405E-05"
        ixy="1.83715726415676E-08"
        ixz="8.33510850473083E-08"
        iyy="0.000289172806004895"
        iyz="8.21285515528094E-09"
        izz="0.000318147083571138" />
    </inertial>
    <visual>
      <origin
        xyz="0 0 0"
        rpy="0 0 0" />
      <geometry>
        <mesh
          filename="package://meta_wl/meshes/l_lower.STL" />
      </geometry>
      <material
        name="">
        <color
          rgba="1 1 1 0.35" />
      </material>
    </visual>
    <collision>
      <origin
        xyz="0 0 0"
        rpy="0 0 0" />
      <geometry>
        <mesh
          filename="package://meta_wl/meshes/l_lower.STL" />
      </geometry>
    </collision>
  </link>
  <joint
    name="l_knee"
    type="revolute">
    <origin
      xyz="0.1566 0 0.00125"
      rpy="0 0 1.6628" />
    <parent
      link="l_upper" />
    <child
      link="l_lower" />
    <axis
      xyz="0 0 1" />
    <limit
      lower="-0.53793"
      upper="0.83588"
      effort="0"
      velocity="0" />
  </joint>
  <link
    name="l_foot">
    <inertial>
      <origin
        xyz="-7.95633722548705E-06 4.33734358770699E-06 0.0138462160537152"
        rpy="0 0 0" />
      <mass
        value="0.422534961029166" />
      <inertia
        ixx="0.000517981849196758"
        ixy="2.54682819490607E-10"
        ixz="-8.36937616408255E-10"
        iyy="0.000517921921861573"
        iyz="-1.00784293908614E-08"
        izz="0.000910258617497224" />
    </inertial>
    <visual>
      <origin
        xyz="0 0 0"
        rpy="0 0 0" />
      <geometry>
        <mesh
          filename="package://meta_wl/meshes/l_foot.STL" />
      </geometry>
      <material
        name="">
        <color
          rgba="1 1 1 0.35" />
      </material>
    </visual>
    <collision>
      <origin
        xyz="0 0 0"
        rpy="0 0 0" />
      <geometry>
        <mesh
          filename="package://meta_wl/meshes/l_foot.STL" />
      </geometry>
    </collision>
  </link>
  <joint
    name="l_wheel"
    type="revolute">
    <origin
      xyz="0.1425 0 -0.0508"
      rpy="0 0 0.58297" />
    <parent
      link="l_lower" />
    <child
      link="l_foot" />
    <axis
      xyz="0 0 1" />
    <limit
      lower="0"
      upper="0"
      effort="0"
      velocity="0" />
  </joint>
  <link
    name="r_upper">
    <inertial>
      <origin
        xyz="0.0671852310993693 -3.00342681036336E-17 -0.00249999999999978"
        rpy="0 0 0" />
      <mass
        value="0.0344820345885739" />
      <inertia
        ixx="3.92026657716492E-06"
        ixy="2.30816478126797E-20"
        ixz="2.52872020236765E-21"
        iyy="9.12501321073414E-05"
        iyz="-5.06305924488066E-22"
        izz="9.50286734754055E-05" />
    </inertial>
    <visual>
      <origin
        xyz="0 0 0"
        rpy="0 0 0" />
      <geometry>
        <mesh
          filename="package://meta_wl/meshes/r_upper.STL" />
      </geometry>
      <material
        name="">
        <color
          rgba="1 1 1 0.35" />
      </material>
    </visual>
    <collision>
      <origin
        xyz="0 0 0"
        rpy="0 0 0" />
      <geometry>
        <mesh
          filename="package://meta_wl/meshes/r_upper.STL" />
      </geometry>
    </collision>
  </link>
  <joint
    name="r_hip"
    type="revolute">
    <origin
      xyz="-0.237 0 0"
      rpy="-1.5708 0.89586 1.5708" />
    <parent
      link="base_link" />
    <child
      link="r_upper" />
    <axis
      xyz="0 0 1" />
    <limit
      lower="-0.436"
      upper="0.262"
      effort="0"
      velocity="0" />
  </joint>
  <link
    name="r_lower">
    <inertial>
      <origin
        xyz="0.115164055925419 0.00102859006399245 -0.00774163353637308"
        rpy="0 0 0" />
      <mass
        value="0.265879317024864" />
      <inertia
        ixx="5.44823409060261E-05"
        ixy="-3.67163352643288E-07"
        ixz="6.19715309386429E-08"
        iyy="0.000304020096087618"
        iyz="-1.49228657979617E-07"
        izz="0.00033742019347885" />
    </inertial>
    <visual>
      <origin
        xyz="0 0 0"
        rpy="0 0 0" />
      <geometry>
        <mesh
          filename="package://meta_wl/meshes/r_lower.STL" />
      </geometry>
      <material
        name="">
        <color
          rgba="1 1 1 0.35" />
      </material>
    </visual>
    <collision>
      <origin
        xyz="0 0 0"
        rpy="0 0 0" />
      <geometry>
        <mesh
          filename="package://meta_wl/meshes/r_lower.STL" />
      </geometry>
    </collision>
  </link>
  <joint
    name="r_knee"
    type="revolute">
    <origin
      xyz="0.1566 0 -0.00125"
      rpy="0 0 1.6628" />
    <parent
      link="r_upper" />
    <child
      link="r_lower" />
    <axis
      xyz="0 0 1" />
    <limit
      lower="-0.53793"
      upper="0.83588"
      effort="0"
      velocity="0" />
  </joint>
  <link
    name="r_foot">
    <inertial>
      <origin
        xyz="-4.80765945579109E-06 2.77533417913922E-06 -0.0138462160537151"
        rpy="0 0 0" />
      <mass
        value="0.422534961029166" />
      <inertia
        ixx="0.000517970577978402"
        ixy="-8.30976625242252E-09"
        ixz="7.51828545974703E-09"
        iyy="0.000517933193079929"
        iyz="6.76391804461815E-09"
        izz="0.000910258617497225" />
    </inertial>
    <visual>
      <origin
        xyz="0 0 0"
        rpy="0 0 0" />
      <geometry>
        <mesh
          filename="package://meta_wl/meshes/r_foot.STL" />
      </geometry>
      <material
        name="">
        <color
          rgba="1 1 1 0.35" />
      </material>
    </visual>
    <collision>
      <origin
        xyz="0 0 0"
        rpy="0 0 0" />
      <geometry>
        <mesh
          filename="package://meta_wl/meshes/r_foot.STL" />
      </geometry>
    </collision>
  </link>
  <joint
    name="r_wheel"
    type="revolute">
    <origin
      xyz="0.1425 0 0.0508"
      rpy="0 0 0.58297" />
    <parent
      link="r_lower" />
    <child
      link="r_foot" />
    <axis
      xyz="0 0 1" />
    <limit
      lower="0"
      upper="0"
      effort="0"
      velocity="0" />
  </joint>
</robot>