<?xml version="1.0" encoding="utf-8"?>
<!-- This URDF was automatically created by SolidWorks to URDF Exporter! Originally created by Stephen Brawner (brawner@gmail.com) 
     Commit Version: 1.6.0-4-g7f85cfe  Build Version: 1.6.7995.38578
     For more information, please see http://wiki.ros.org/sw_urdf_exporter -->
<robot
  name="meta_wl">
  <link
    name="base">
    <inertial>
      <origin
        xyz="-27.027E-3 8.668E-3 51.737E-3"
        rpy="0 0 0" />
      <mass
        value="3.422" />
      <inertia
        ixx="16516E-6"
        ixy="408E-6"
        ixz="-1864E-6"
        iyy="12477E-6"
        iyz="301E-6"
        izz="22170E-6" />
    </inertial>
    <visual>
      <origin
        xyz="0 0 0"
        rpy="0 0 0" />
      <geometry>
        <mesh
          filename="../meshes/base.STL" />
      </geometry>
      <material
        name="">
        <color
          rgba="1 1 1 0.35" />
      </material>
    </visual>
    <collision>
      <origin
        xyz="0 0 0"
        rpy="0 0 0" />
      <geometry>
        <mesh
          filename="../meshes/base.STL" />
      </geometry>
    </collision>
  </link>
  <link
    name="l_thigh">
    <inertial>
      <origin
        xyz="0.0671852310993693 -8.35570846580197E-18 0.00250000000000011"
        rpy="0 0 0" />
      <mass
        value="0.0344820345885739" />
      <inertia
        ixx="3.92026657716492E-06"
        ixy="1.03761536038652E-20"
        ixz="6.56662359828351E-22"
        iyy="9.12501321073414E-05"
        iyz="-9.73859650538212E-22"
        izz="9.50286734754055E-05" />
    </inertial>
    <visual>
      <origin
        xyz="0 0 0"
        rpy="0 0 0" />
      <geometry>
        <mesh
          filename="../meshes/l_thigh.STL" />
      </geometry>
      <material
        name="">
        <color
          rgba="1 1 1 0.35" />
      </material>
    </visual>
    <collision>
      <origin
        xyz="0 0 0"
        rpy="0 0 0" />
      <geometry>
        <mesh
          filename="../meshes/l_thigh.STL" />
      </geometry>
    </collision>
  </link>
  <joint
    name="l_hip"
    type="revolute">
    <origin
      xyz="-0.02 0.121 0.066"
      rpy="-1.5708 0.816 -3.1416" />
    <parent
      link="base" />
    <child
      link="l_thigh" />
    <axis
      xyz="0 0 1" />
    <limit
      lower="-0.436"
      upper="0.262"
      effort="30"
      velocity="1000" />
    <dynamics
      damping="0"
      friction="0" />
  </joint>
  <link
    name="l_shin">
    <inertial>
      <origin
        xyz="0.0649693737417057 6.79456491070596E-14 0.00124999999999971"
        rpy="0 0 0" />
      <mass
        value="0.086125018064217" />
      <inertia
        ixx="1.84648350058641E-05"
        ixy="-3.294720995594E-16"
        ixz="-5.87349482843795E-20"
        iyy="0.00026875213569075"
        iyz="5.62290965943952E-21"
        izz="0.000286858342492397" />
    </inertial>
    <visual>
      <origin
        xyz="0 0 0"
        rpy="0 0 0" />
      <geometry>
        <mesh
          filename="../meshes/l_shin.STL" />
      </geometry>
      <material
        name="">
        <color
          rgba="1 1 1 0.35" />
      </material>
    </visual>
    <collision>
      <origin
        xyz="0 0 0"
        rpy="0 0 0" />
      <geometry>
        <mesh
          filename="../meshes/l_shin.STL" />
      </geometry>
    </collision>
  </link>
  <joint
    name="l_knee"
    type="revolute">
    <origin
      xyz="0.1566 0 0.00125"
      rpy="0 0 1.8118" />
    <parent
      link="l_thigh" />
    <child
      link="l_shin" />
    <axis
      xyz="0 0 1" />
    <limit
      lower="-0.538"
      upper="0.836"
      effort="30"
      velocity="1000" />
    <dynamics
      damping="0"
      friction="0" />
  </joint>
  <link
    name="l_foot">
    <inertial>
      <origin
        xyz="-1.23949461805495E-13 -2.42861286636753E-14 0.0139999999999938"
        rpy="0 0 0" />
      <mass
        value="0.363247599426668" />
      <inertia
        ixx="0.000498536075854535"
        ixy="4.79848234963671E-20"
        ixz="-1.89973112526103E-19"
        iyy="0.000498536075854535"
        iyz="8.68147548945964E-19"
        izz="0.000872747056357901" />
    </inertial>
    <visual>
      <origin
        xyz="0 0 0"
        rpy="0 0 0" />
      <geometry>
        <mesh
          filename="../meshes/l_foot.STL" />
      </geometry>
      <material
        name="">
        <color
          rgba="1 1 1 0.35" />
      </material>
    </visual>
    <collision>
      <origin
        xyz="0 0 0"
        rpy="0 0 0" />
      <geometry>
        <mesh
          filename="../meshes/l_foot.STL" />
      </geometry>
    </collision>
  </link>
  <joint
    name="l_wheel"
    type="revolute">
    <origin
      xyz="0.1425 0 -0.0508"
      rpy="0 0 0.51383" />
    <parent
      link="l_shin" />
    <child
      link="l_foot" />
    <axis
      xyz="0 0 1" />
    <limit
      effort="5"
      velocity="1000" />
    <dynamics
      damping="0"
      friction="0" />
  </joint>
  <link
    name="r_thigh">
    <inertial>
      <origin
        xyz="0.0671852310993694 -4.03005402468748E-17 -0.00250000000000022"
        rpy="0 0 0" />
      <mass
        value="0.0344820345885738" />
      <inertia
        ixx="3.92026657716492E-06"
        ixy="-1.10537799616686E-19"
        ixz="-3.11190307404087E-21"
        iyy="9.12501321073411E-05"
        iyz="8.44396102702677E-22"
        izz="9.50286734754053E-05" />
    </inertial>
    <visual>
      <origin
        xyz="0 0 0"
        rpy="0 0 0" />
      <geometry>
        <mesh
          filename="../meshes/r_thigh.STL" />
      </geometry>
      <material
        name="">
        <color
          rgba="1 1 1 0.35" />
      </material>
    </visual>
    <collision>
      <origin
        xyz="0 0 0"
        rpy="0 0 0" />
      <geometry>
        <mesh
          filename="../meshes/r_thigh.STL" />
      </geometry>
    </collision>
  </link>
  <joint
    name="r_hip"
    type="revolute">
    <origin
      xyz="-0.02 -0.121 0.066"
      rpy="-1.5708 0.816 3.1416" />
    <parent
      link="base" />
    <child
      link="r_thigh" />
    <axis
      xyz="0 0 1" />
    <limit
      lower="-0.436"
      upper="0.262"
      effort="30"
      velocity="1000" />
    <dynamics
      damping="0"
      friction="0" />
  </joint>
  <link
    name="r_shin">
    <inertial>
      <origin
        xyz="0.0649693737417057 -1.0325074129014E-13 -0.00124999999999983"
        rpy="0 0 0" />
      <mass
        value="0.0861250180642172" />
      <inertia
        ixx="1.84648350058642E-05"
        ixy="3.29651670544218E-16"
        ixz="4.46729222348408E-20"
        iyy="0.000268752135690751"
        iyz="-4.77722496474428E-21"
        izz="0.000286858342492398" />
    </inertial>
    <visual>
      <origin
        xyz="0 0 0"
        rpy="0 0 0" />
      <geometry>
        <mesh
          filename="../meshes/r_shin.STL" />
      </geometry>
      <material
        name="">
        <color
          rgba="1 1 1 0.35" />
      </material>
    </visual>
    <collision>
      <origin
        xyz="0 0 0"
        rpy="0 0 0" />
      <geometry>
        <mesh
          filename="../meshes/r_shin.STL" />
      </geometry>
    </collision>
  </link>
  <joint
    name="r_knee"
    type="revolute">
    <origin
      xyz="0.1566 0 -0.00125"
      rpy="0 0 1.8118" />
    <parent
      link="r_thigh" />
    <child
      link="r_shin" />
    <axis
      xyz="0 0 1" />
    <limit
      lower="-0.538"
      upper="0.836"
      effort="30"
      velocity="1000" />
    <dynamics
      damping="0"
      friction="0" />
  </joint>
  <link
    name="r_foot">
    <inertial>
      <origin
        xyz="-1.21957999255073E-13 -1.61815005839117E-14 -0.0139999999999951"
        rpy="0 0 0" />
      <mass
        value="0.363247599426668" />
      <inertia
        ixx="0.000498536075854535"
        ixy="4.4283813060641E-20"
        ixz="1.61352111169201E-19"
        iyy="0.000498536075854535"
        iyz="-8.67475637400023E-19"
        izz="0.000872747056357902" />
    </inertial>
    <visual>
      <origin
        xyz="0 0 0"
        rpy="0 0 0" />
      <geometry>
        <mesh
          filename="../meshes/r_foot.STL" />
      </geometry>
      <material
        name="">
        <color
          rgba="1 1 1 0.35" />
      </material>
    </visual>
    <collision>
      <origin
        xyz="0 0 0"
        rpy="0 0 0" />
      <geometry>
        <mesh
          filename="../meshes/r_foot.STL" />
      </geometry>
    </collision>
  </link>
  <joint
    name="r_wheel"
    type="revolute">
    <origin
      xyz="0.1425 0 0.0508"
      rpy="0 0 0.51383" />
    <parent
      link="r_shin" />
    <child
      link="r_foot" />
    <axis
      xyz="0 0 1" />
    <limit
      effort="5"
      velocity="1000" />
    <dynamics
      damping="0"
      friction="0" />
  </joint>
</robot>