<?xml version="1.0" encoding="utf-8"?>
<!-- This URDF was automatically created by SolidWorks to URDF Exporter! Originally created by Stephen Brawner (brawner@gmail.com) 
     Commit Version: 1.6.0-4-g7f85cfe  Build Version: 1.6.7995.38578
     For more information, please see http://wiki.ros.org/sw_urdf_exporter -->
<robot
  name="meta_wl">
  <link
    name="base_link">
    <inertial>
      <origin
        xyz="-0.0245766710804395 1.12954262751902E-05 0.0551837979582068"
        rpy="0 0 0" />
      <mass
        value="3.422" />
      <inertia
        ixx="16516E-6"
        ixy="408E-6"
        ixz="-1864E-6"
        iyy="12477E-6"
        iyz="301E-6"
        izz="22170E-6" />
    </inertial>
    <visual>
      <origin
        xyz="0 0 0"
        rpy="0 0 0" />
      <geometry>
        <mesh
          filename="../meshes/base_link.STL" />
      </geometry>
      <material
        name="">
        <color
          rgba="1 1 1 0.35" />
      </material>
    </visual>
    <collision>
      <origin
        xyz="0 0 0"
        rpy="0 0 0" />
      <geometry>
        <mesh
          filename="../meshes/base_link.STL" />
      </geometry>
    </collision>
  </link>
  <link
    name="l_leg_link">
    <inertial>
      <origin
        xyz="0.167137810001204 0.0899559625004974 0.00695176949094712"
        rpy="0 0 0" />
      <mass
        value="0.205618463841969" />
      <inertia
        ixx="0.00046553666866474"
        ixy="-4.84637387403824E-05"
        ixz="5.46297742111448E-08"
        iyy="4.41718311000394E-05"
        iyz="5.54929141091411E-08"
        izz="0.000498095795724903" />
    </inertial>
    <visual>
      <origin
        xyz="0 0 0"
        rpy="0 0 0" />
      <geometry>
        <mesh
          filename="../meshes/l_leg_link.STL" />
      </geometry>
      <material
        name="">
        <color
          rgba="0.752941176470588 0.752941176470588 0.752941176470588 1" />
      </material>
    </visual>
    <collision>
      <origin
        xyz="0 0 0"
        rpy="0 0 0" />
      <geometry>
        <mesh
          filename="../meshes/l_leg_link.STL" />
      </geometry>
    </collision>
  </link>
  <joint
    name="l_leg_joint"
    type="prismatic">
    <origin
      xyz="-0.02 0.121 0.066"
      rpy="-1.5708 1.0033 3.1416" />
    <parent
      link="base_link" />
    <child
      link="l_leg_link" />
    <axis
      xyz="0.72714 0.68649 0" />
    <limit
      lower="-0.436"
      upper="0.262"
      effort="30"
      velocity="1000" />
    <dynamics
      damping="0"
      friction="0" />
  </joint>
  <link
    name="l_wheel_link">
    <inertial>
      <origin
        xyz="-2.24126273096203E-14 8.40993941153556E-14 0.0139999999999988"
        rpy="0 0 0" />
      <mass
        value="0.363247599426668" />
      <inertia
        ixx="0.000498536075854535"
        ixy="-2.91728214437939E-20"
        ixz="-1.82213908907247E-19"
        iyy="0.000498536075854535"
        iyz="6.53614897137412E-19"
        izz="0.000872747056357901" />
    </inertial>
    <visual>
      <origin
        xyz="0 0 0"
        rpy="0 0 0" />
      <geometry>
        <mesh
          filename="../meshes/l_wheel_link.STL" />
      </geometry>
      <material
        name="">
        <color
          rgba="1 1 1 0.35" />
      </material>
    </visual>
    <collision>
      <origin
        xyz="0 0 0"
        rpy="0 0 0" />
      <geometry>
        <mesh
          filename="../meshes/l_wheel_link.STL" />
      </geometry>
    </collision>
  </link>
  <joint
    name="l_wheel_joint"
    type="continuous">
    <origin
      xyz="0.17292 0.14156 -0.04955"
      rpy="0 0 2.1383" />
    <parent
      link="l_leg_link" />
    <child
      link="l_wheel_link" />
    <axis
      xyz="0 0 1" />
  </joint>
  <link
    name="r_leg_link">
    <inertial>
      <origin
        xyz="0.167088762600156 0.0899465472498976 -0.00195176952340823"
        rpy="0 0 0" />
      <mass
        value="0.205618464210299" />
      <inertia
        ixx="0.000465594895859004"
        ixy="-4.86098121999377E-05"
        ixz="7.1294683245929E-08"
        iyy="4.41136039089308E-05"
        iyz="-3.13200238715791E-08"
        izz="0.000498095795726478" />
    </inertial>
    <visual>
      <origin
        xyz="0 0 0"
        rpy="0 0 0" />
      <geometry>
        <mesh
          filename="../meshes/r_leg_link.STL" />
      </geometry>
      <material
        name="">
        <color
          rgba="1 1 1 0.35" />
      </material>
    </visual>
    <collision>
      <origin
        xyz="0 0 0"
        rpy="0 0 0" />
      <geometry>
        <mesh
          filename="../meshes/r_leg_link.STL" />
      </geometry>
    </collision>
  </link>
  <joint
    name="r_leg_joint"
    type="prismatic">
    <origin
      xyz="-0.02 -0.116 0.066"
      rpy="-1.5708 1.0033 3.1416" />
    <parent
      link="base_link" />
    <child
      link="r_leg_link" />
    <axis
      xyz="0.72714 0.68649 0" />
    <limit
      lower="-0.436"
      upper="0.262"
      effort="30"
      velocity="1000" />
    <dynamics
      damping="0"
      friction="0" />
  </joint>
  <link
    name="r_wheel_link">
    <inertial>
      <origin
        xyz="1.34441069388203E-14 -5.85087533977457E-14 -0.0140000000000002"
        rpy="0 0 0" />
      <mass
        value="0.363247599426668" />
      <inertia
        ixx="0.000498536075854535"
        ixy="8.16732701031044E-21"
        ixz="-2.66467760966762E-20"
        iyy="0.000498536075854535"
        iyz="9.529283117045E-20"
        izz="0.000872747056357902" />
    </inertial>
    <visual>
      <origin
        xyz="0 0 0"
        rpy="0 0 0" />
      <geometry>
        <mesh
          filename="../meshes/r_wheel_link.STL" />
      </geometry>
      <material
        name="">
        <color
          rgba="1 1 1 0.35" />
      </material>
    </visual>
    <collision>
      <origin
        xyz="0 0 0"
        rpy="0 0 0" />
      <geometry>
        <mesh
          filename="../meshes/r_wheel_link.STL" />
      </geometry>
    </collision>
  </link>
  <joint
    name="r_wheel_joint"
    type="continuous">
    <origin
      xyz="0.17292 0.14156 0.05455"
      rpy="0 0 2.1383" />
    <parent
      link="r_leg_link" />
    <child
      link="r_wheel_link" />
    <axis
      xyz="0 0 1" />
  </joint>
</robot>